<?xml version="1.0" ?>
<robot name="IAMSOEBALSYA" xmlns:xacro="http://www.ros.org/wiki/xacro">

<xacro:include filename="$(find IAMSOEBALSYA_description)/urdf/materials.xacro" />
<xacro:include filename="$(find IAMSOEBALSYA_description)/urdf/IAMSOEBALSYA.trans" />
<xacro:include filename="$(find IAMSOEBALSYA_description)/urdf/IAMSOEBALSYA.gazebo" />
<link name="base_link">
  <inertial>
    <origin xyz="0.005425708344292985 -0.01755120479966109 0.33567552360050373" rpy="0 0 0"/>
    <mass value="16.785969107603197"/>
    <inertia ixx="2.522419" iyy="3.039042" izz="1.00077" ixy="0.000111" iyz="-0.162886" ixz="-2.9e-05"/>
  </inertial>
  <visual>
    <origin xyz="0 0 0" rpy="0 0 0"/>
    <geometry>
      <mesh filename="package://IAMSOEBALSYA_description/meshes/base_link.stl" scale="0.001 0.001 0.001"/>
    </geometry>
    <material name="silver"/>
  </visual>
  <collision>
    <origin xyz="0 0 0" rpy="0 0 0"/>
    <geometry>
      <mesh filename="package://IAMSOEBALSYA_description/meshes/base_link.stl" scale="0.001 0.001 0.001"/>
    </geometry>
  </collision>
</link>

<link name="upanddown_1">
  <inertial>
    <origin xyz="0.1726719078517017 0.03555352143195987 0.03527515361879649" rpy="0 0 0"/>
    <mass value="1.147226288823926"/>
    <inertia ixx="0.001656" iyy="0.022888" izz="0.023523" ixy="-5e-06" iyz="6e-06" ixz="-2.1e-05"/>
  </inertial>
  <visual>
    <origin xyz="0.142927 0.023082 -0.136634" rpy="0 0 0"/>
    <geometry>
      <mesh filename="package://IAMSOEBALSYA_description/meshes/upanddown_1.stl" scale="0.001 0.001 0.001"/>
    </geometry>
    <material name="silver"/>
  </visual>
  <collision>
    <origin xyz="0.142927 0.023082 -0.136634" rpy="0 0 0"/>
    <geometry>
      <mesh filename="package://IAMSOEBALSYA_description/meshes/upanddown_1.stl" scale="0.001 0.001 0.001"/>
    </geometry>
  </collision>
</link>

<link name="motorandbear_1">
  <inertial>
    <origin xyz="0.21691139994480768 0.0004629689620064565 0.000605404831110351" rpy="0 0 0"/>
    <mass value="0.5697868468767003"/>
    <inertia ixx="0.000588" iyy="0.001828" izz="0.001827" ixy="-2e-06" iyz="8e-06" ixz="-4e-06"/>
  </inertial>
  <visual>
    <origin xyz="0.12552 -0.012418 -0.171634" rpy="0 0 0"/>
    <geometry>
      <mesh filename="package://IAMSOEBALSYA_description/meshes/motorandbear_1.stl" scale="0.001 0.001 0.001"/>
    </geometry>
    <material name="silver"/>
  </visual>
  <collision>
    <origin xyz="0.12552 -0.012418 -0.171634" rpy="0 0 0"/>
    <geometry>
      <mesh filename="package://IAMSOEBALSYA_description/meshes/motorandbear_1.stl" scale="0.001 0.001 0.001"/>
    </geometry>
  </collision>
</link>

<link name="hip_1">
  <inertial>
    <origin xyz="-0.09025229203315212 0.001890496534878024 0.0004015977398102444" rpy="0 0 0"/>
    <mass value="1.0124305913369196"/>
    <inertia ixx="0.000792" iyy="0.002699" izz="0.002143" ixy="0.0" iyz="-2e-06" ixz="4e-06"/>
  </inertial>
  <visual>
    <origin xyz="-0.086434 -0.012369 -0.171631" rpy="0 0 0"/>
    <geometry>
      <mesh filename="package://IAMSOEBALSYA_description/meshes/hip_1.stl" scale="0.001 0.001 0.001"/>
    </geometry>
    <material name="silver"/>
  </visual>
  <collision>
    <origin xyz="-0.086434 -0.012369 -0.171631" rpy="0 0 0"/>
    <geometry>
      <mesh filename="package://IAMSOEBALSYA_description/meshes/hip_1.stl" scale="0.001 0.001 0.001"/>
    </geometry>
  </collision>
</link>

<link name="bedro_1">
  <inertial>
    <origin xyz="0.05026342958228973 0.05646726293137333 -0.02245991848982623" rpy="0 0 0"/>
    <mass value="1.7395147003134657"/>
    <inertia ixx="0.005161" iyy="0.018372" izz="0.015952" ixy="-0.001577" iyz="0.000691" ixz="0.005876"/>
  </inertial>
  <visual>
    <origin xyz="0.004233 -0.032538 -0.171631" rpy="0 0 0"/>
    <geometry>
      <mesh filename="package://IAMSOEBALSYA_description/meshes/bedro_1.stl" scale="0.001 0.001 0.001"/>
    </geometry>
    <material name="silver"/>
  </visual>
  <collision>
    <origin xyz="0.004233 -0.032538 -0.171631" rpy="0 0 0"/>
    <geometry>
      <mesh filename="package://IAMSOEBALSYA_description/meshes/bedro_1.stl" scale="0.001 0.001 0.001"/>
    </geometry>
  </collision>
</link>

<link name="foot_1">
  <inertial>
    <origin xyz="-0.1308761889614943 -0.04132844307914155 -0.0165036312282135" rpy="0 0 0"/>
    <mass value="0.6520464054946541"/>
    <inertia ixx="0.00029" iyy="0.009999" izz="0.00983" ixy="-9.7e-05" iyz="-3e-06" ixz="-0.000317"/>
  </inertial>
  <visual>
    <origin xyz="-0.27037 -0.147629 -0.050396" rpy="0 0 0"/>
    <geometry>
      <mesh filename="package://IAMSOEBALSYA_description/meshes/foot_1.stl" scale="0.001 0.001 0.001"/>
    </geometry>
    <material name="silver"/>
  </visual>
  <collision>
    <origin xyz="-0.27037 -0.147629 -0.050396" rpy="0 0 0"/>
    <geometry>
      <mesh filename="package://IAMSOEBALSYA_description/meshes/foot_1.stl" scale="0.001 0.001 0.001"/>
    </geometry>
  </collision>
</link>

<link name="sock_1">
  <inertial>
    <origin xyz="-0.005679678780149307 0.01705331690783861 -0.016914529895272406" rpy="0 0 0"/>
    <mass value="0.16627128991129425"/>
    <inertia ixx="0.000103" iyy="9.7e-05" izz="9.4e-05" ixy="-0.0" iyz="-0.0" ixz="6e-06"/>
  </inertial>
  <visual>
    <origin xyz="0.025909 -0.090243 -0.045146" rpy="0 0 0"/>
    <geometry>
      <mesh filename="package://IAMSOEBALSYA_description/meshes/sock_1.stl" scale="0.001 0.001 0.001"/>
    </geometry>
    <material name="silver"/>
  </visual>
  <collision>
    <origin xyz="0.025909 -0.090243 -0.045146" rpy="0 0 0"/>
    <geometry>
      <mesh filename="package://IAMSOEBALSYA_description/meshes/sock_1.stl" scale="0.001 0.001 0.001"/>
    </geometry>
  </collision>
</link>

<joint name="Slider_1" type="prismatic">
  <origin xyz="-0.142927 -0.023082 0.136634" rpy="0 0 0"/>
  <parent link="base_link"/>
  <child link="upanddown_1"/>
  <axis xyz="4e-06 -0.0 -1.0"/>
  <limit upper="0.0" lower="-0.532" effort="100" velocity="100"/>
</joint>

<joint name="Rigid_2" type="fixed">
  <origin xyz="0.017407 0.0355 0.035" rpy="0 0 0"/>
  <parent link="upanddown_1"/>
  <child link="motorandbear_1"/>
</joint>

<joint name="Revolute_3" type="revolute">
  <origin xyz="0.211954 -4.9e-05 -3e-06" rpy="0 0 0"/>
  <parent link="motorandbear_1"/>
  <child link="hip_1"/>
  <axis xyz="1.0 -0.000217 4e-06"/>
  <limit upper="0.961676" lower="-0.436332" effort="100" velocity="100"/>
</joint>

<joint name="Revolute_4" type="revolute">
  <origin xyz="-0.090667 0.020169 0.0" rpy="0 0 0"/>
  <parent link="hip_1"/>
  <child link="bedro_1"/>
  <axis xyz="-0.000217 -1.0 0.0"/>
  <limit upper="0.087266" lower="-2.617994" effort="100" velocity="100"/>
</joint>

<joint name="Revolute_5" type="revolute">
  <origin xyz="0.274603 0.115091 -0.121235" rpy="0 0 0"/>
  <parent link="bedro_1"/>
  <child link="foot_1"/>
  <axis xyz="0.000217 1.0 -0.0"/>
  <limit upper="0.0" lower="-2.181662" effort="100" velocity="100"/>
</joint>

<joint name="Rigid_6" type="fixed">
  <origin xyz="-0.296279 -0.057386 -0.00525" rpy="0 0 0"/>
  <parent link="foot_1"/>
  <child link="sock_1"/>
</joint>

</robot>
